Workbook

Sheet 검토 현황
A1: 대전 식당 후보 검토 현황
A4: 추천 점수는 검토 순서입니다. 네이버 지도와 최근 블로그를 확인한 뒤 후보 검토 시트의 상태를 변경하세요.
A6: 미검토 | D6: 승인 | G6: 보류 | J6: 제외 | M6: 전체 후보
A7: =COUNTIF('후보 검토'!$A$2:$A$461,"pending") -> 438 | D7: =COUNTIF('후보 검토'!$A$2:$A$461,"approved") -> 0 | G7: =COUNTIF('후보 검토'!$A$2:$A$461,"hold") -> 0 | J7: =COUNTIF('후보 검토'!$A$2:$A$461,"rejected") -> 22 | M7: =COUNTA('후보 검토'!$C$2:$C$461) -> 460
A11: 구 | B11: 전체 | C11: 미검토 | D11: 승인 | E11: 보류 | F11: 제외
A12: 대덕구 | B12: =COUNTIF('후보 검토'!$B$2:$B$461,A12) -> 100 | C12: =COUNTIFS('후보 검토'!$B$2:$B$461,A12,'후보 검토'!$A$2:$A$461,"pending") -> 95 | D12: =COUNTIFS('후보 검토'!$B$2:$B$461,A12,'후보 검토'!$A$2:$A$461,"approved") -> 0 | E12: =COUNTIFS('후보 검토'!$B$2:$B$461,A12,'후보 검토'!$A$2:$A$461,"hold") -> 0 | F12: =COUNTIFS('후보 검토'!$B$2:$B$461,A12,'후보 검토'!$A$2:$A$461,"rejected") -> 5
A13: 동구 | B13: =COUNTIF('후보 검토'!$B$2:$B$461,A13) -> 100 | C13: =COUNTIFS('후보 검토'!$B$2:$B$461,A13,'후보 검토'!$A$2:$A$461,"pending") -> 91 | D13: =COUNTIFS('후보 검토'!$B$2:$B$461,A13,'후보 검토'!$A$2:$A$461,"approved") -> 0 | E13: =COUNTIFS('후보 검토'!$B$2:$B$461,A13,'후보 검토'!$A$2:$A$461,"hold") -> 0 | F13: =COUNTIFS('후보 검토'!$B$2:$B$461,A13,'후보 검토'!$A$2:$A$461,"rejected") -> 9
A14: 서구 | B14: =COUNTIF('후보 검토'!$B$2:$B$461,A14) -> 100 | C14: =COUNTIFS('후보 검토'!$B$2:$B$461,A14,'후보 검토'!$A$2:$A$461,"pending") -> 99 | D14: =COUNTIFS('후보 검토'!$B$2:$B$461,A14,'후보 검토'!$A$2:$A$461,"approved") -> 0 | E14: =COUNTIFS('후보 검토'!$B$2:$B$461,A14,'후보 검토'!$A$2:$A$461,"hold") -> 0 | F14: =COUNTIFS('후보 검토'!$B$2:$B$461,A14,'후보 검토'!$A$2:$A$461,"rejected") -> 1
A15: 유성구 | B15: =COUNTIF('후보 검토'!$B$2:$B$461,A15) -> 100 | C15: =COUNTIFS('후보 검토'!$B$2:$B$461,A15,'후보 검토'!$A$2:$A$461,"pending") -> 95 | D15: =COUNTIFS('후보 검토'!$B$2:$B$461,A15,'후보 검토'!$A$2:$A$461,"approved") -> 0 | E15: =COUNTIFS('후보 검토'!$B$2:$B$461,A15,'후보 검토'!$A$2:$A$461,"hold") -> 0 | F15: =COUNTIFS('후보 검토'!$B$2:$B$461,A15,'후보 검토'!$A$2:$A$461,"rejected") -> 5
A16: 중구 | B16: =COUNTIF('후보 검토'!$B$2:$B$461,A16) -> 60 | C16: =COUNTIFS('후보 검토'!$B$2:$B$461,A16,'후보 검토'!$A$2:$A$461,"pending") -> 58 | D16: =COUNTIFS('후보 검토'!$B$2:$B$461,A16,'후보 검토'!$A$2:$A$461,"approved") -> 0 | E16: =COUNTIFS('후보 검토'!$B$2:$B$461,A16,'후보 검토'!$A$2:$A$461,"hold") -> 0 | F16: =COUNTIFS('후보 검토'!$B$2:$B$461,A16,'후보 검토'!$A$2:$A$461,"rejected") -> 2
A17: 합계 | B17: =SUM(B12:B16) -> 460 | C17: =SUM(C12:C16) -> 438 | D17: =SUM(D12:D16) -> 0 | E17: =SUM(E12:E16) -> 0 | F17: =SUM(F12:F16) -> 22

Sheet 후보 검토
A1: 검토 상태 review_status | B1: 구 district | C1: 상호명 name | D1: 업종 category | E1: 추천 점수 recommendation_score | F1: 추천 이유 recommendation_reason | G1: 지번 주소 address | H1: 도로명 주소 road_address | I1: 블로그 확인 blog_search_url | J1: 업체 링크 naver_link | K1: 중복 가능성 possible_duplicate | L1: 제외 사유 reject_reason | M1: 최근 게시일 latest_post_date | N1: 최근 글 수 recent_blog_count | O1: 블로거 수 distinct_blogger_count | P1: 검색 결과 수 blog_result_count | Q1: 지역 노출 수 local_hit_count | R1: 리뷰순 노출 수 comment_sort_hit_count | S1: 발견 검색어 matched_queries | T1: 위도 latitude | U1: 경도 longitude
A2: pending | B2: 대덕구 | C2: 맛집부추해물칼국수 | D2: 한식>칼국수,만두 | E2: 87 | F2: 지역성: 칼국수; 최근 12개월 블로그 100건 | G2: 대전광역시 대덕구 신탄진동 139-24 | H2: 대전광역시 대덕구 신탄진로804번길 31 | I2: =HYPERLINK("https://search.naver.com/search.naver?where=blog&query=%EB%A7%9B%EC%A7%91%EB%B6%80%EC%B6%94%ED%95%B4%EB%AC%BC%EC%B9%BC%EA%B5%AD%EC%88%98+%EB%8C%80%EB%8D%95%EA%B5%AC","블로그 보기") -> 블로그 보기 | M2: 46223 | N2: 100 | O2: 99 | P2: 95913 | Q2: 9 | R2: 4 | S2: 대덕구 칼국수 | 대덕구 해산물 | 신탄진 맛집 | 신탄진 칼국수 | 신탄진 한식 | 신탄진 해산물 | T2: 36.449557 | U2: 127.43159
A3: pending | B3: 대덕구 | C3: 교동면옥 대전중리점 | D3: 한식>냉면 | E3: 84 | F3: 지역성: 대전; 최근 12개월 블로그 100건 | G3: 대전광역시 대덕구 중리동 230-1 1층 교동면옥 대전중리점 | H3: 대전광역시 대덕구 한밭대로 1100 1층 교동면옥 대전중리점 | I3: =HYPERLINK("https://search.naver.com/search.naver?where=blog&query=%EA%B5%90%EB%8F%99%EB%A9%B4%EC%98%A5+%EB%8C%80%EC%A0%84%EC%A4%91%EB%A6%AC%EC%A0%90+%EA%B5%90%EB%8F%99","블로그 보기") -> 블로그 보기 | J3: =HYPERLINK("https://www.instagram.com/kyodong_myeonok/","업체 보기") -> 업체 보기 | M3: 46223 | N3: 100 | O3: 71 | P3: 2705 | Q3: 7 | R3: 3 | S3: 대덕구 국밥 | 대덕구 냉면 | 대덕구 맛집 | 대덕구 한식 | T3: 36.358194 | U3: 127.4208
A4: pending | B4: 대덕구 | C4: 우림칼국수 신탄진점 | D4: 음식점>한식>칼국수,만두 | E4: 84 | F4: 지역성: 칼국수; 최근 12개월 블로그 100건 | G4: 대전광역시 대덕구 신탄진동 155-15 우림칼국수 신탄진점 | H4: 대전광역시 대덕구 신탄진동로 16-2 우림칼국수 신탄진점 | I4: =HYPERLINK("https://search.naver.com/search.naver?where=blog&query=%EC%9A%B0%EB%A6%BC%EC%B9%BC%EA%B5%AD%EC%88%98+%EC%8B%A0%ED%83%84%EC%A7%84%EC%A0%90+%EC%8B%A0%ED%83%84%EC%A7%84%EB%8F%99","블로그 보기") -> 블로그 보기 | M4: 46221 | N4: 100 | O4: 100 | P4: 264 | Q4: 5 | R4: 4 | S4: 대덕구 냉면 | 대덕구 칼국수 | 신탄진 냉면 | 신탄진 칼국수 | T4: 36.44741 | U4: 127.43137
A5: pending | B5: 대덕구 | C5: 오문창순대국밥 | D5: 한식>순대,순댓국 | E5: 81 | F5: 최근 12개월 블로그 100건 | G5: 대전광역시 대덕구 중리동 203-2 | H5: 대전광역시 대덕구 한밭대로 1153 | I5: =HYPERLINK("https://search.naver.com/search.naver?where=blog&query=%EC%98%A4%EB%AC%B8%EC%B0%BD%EC%88%9C%EB%8C%80%EA%B5%AD%EB%B0%A5+%EB%8C%80%EB%8D%95%EA%B5%AC","블로그 보기") -> 블로그 보기 | M5: 46223 | N5: 100 | O5: 97 | P5: 2146 | Q5: 7 | R5: 4 | S5: 대덕구 고기 | 대덕구 국밥 | 대덕구 맛집 | 대덕구 한식 | T5: 36.359233 | U5: 127.42657
A6: pending | B6: 대덕구 | C6: 공주쌍신집칼국수 대청댐점 | D6: 한식>칼국수,만두 | E6: 79 | F6: 지역성: 칼국수; 최근 12개월 블로그 100건 | G6: 대전광역시 대덕구 미호동 90-2 1층 | H6: 대전광역시 대덕구 대청로 572 1층 | I6: =HYPERLINK("https://search.naver.com/search.naver?where=blog&query=%EA%B3%B5%EC%A3%BC%EC%8C%8D%EC%8B%A0%EC%A7%91%EC%B9%BC%EA%B5%AD%EC%88%98+%EB%8C%80%EC%B2%AD%EB%8C%90%EC%A0%90+%EB%8C%80%EB%8D%95%EA%B5%AC","블로그 보기") -> 블로그 보기 | J6: =HYPERLINK("https://app.catchtable.co.kr/ct/shop/gongjussangsin","업체 보기") -> 업체 보기 | M6: 46223 | N6: 100 | O6: 92 | P6: 1031 | Q6: 4 | R6: 3 | S6: 대덕구 맛집 | 대덕구 칼국수 | 대덕구 한식 | T6: 36.470008 | U6: 127.47227
A7: pending | B7: 대덕구 | C7: 형제횟집 | D7: 한식>생선회 | E7: 72 | F7: 최근 12개월 블로그 76건 | G7: 대전광역시 대덕구 중리동 372-3 형제횟집 | H7: 대전광역시 대덕구 중리로76번길 22 형제횟집 | I7: =HYPERLINK("https://search.naver.com/search.naver?where=blog&query=%ED%98%95%EC%A0%9C%ED%9A%9F%EC%A7%91+%EB%8C%80%EB%8D%95%EA%B5%AC","블로그 보기") -> 블로그 보기 | M7: 46211 | N7: 76 | O7: 93 | P7: 317 | Q7: 4 | R7: 3 | S7: 대덕구 맛집 | 대덕구 한식 | 대덕구 해산물 | T7: 36.365738 | U7: 127.42639
A8: pending | B8: 대덕구 | C8: 나래원 | D8: 음식점>한식 | E8: 69 | F8: 최근 12개월 블로그 36건 | G8: 대전광역시 대덕구 비래동 139-10 | H8: 대전광역시 대덕구 비래동로16번길 13 | I8: =HYPERLINK("https://search.naver.com/search.naver?where=blog&query=%EB%82%98%EB%9E%98%EC%9B%90+%EB%B9%84%EB%9E%98%EB%8F%99","블로그 보기") -> 블로그 보기 | M8: 46220 | N8: 36 | O8: 81 | P8: 363 | Q8: 4 | R8: 2 | S8: 대덕구 삼계탕 | 비래동 한식 | T8: 36.355186 | U8: 127.45064
A9: pending | B9: 대덕구 | C9: 백마강참숯민물장어 | D9: 한식>장어,먹장어요리 | E9: 68 | F9: 최근 12개월 블로그 31건 | G9: 대전광역시 대덕구 비래동 561-1 | H9: 대전광역시 대덕구 동서대로 1752 | I9: =HYPERLINK("https://search.naver.com/search.naver?where=blog&query=%EB%B0%B1%EB%A7%88%EA%B0%95%EC%B0%B8%EC%88%AF%EB%AF%BC%EB%AC%BC%EC%9E%A5%EC%96%B4+%EB%8C%80%EB%8D%95%EA%B5%AC","블로그 보기") -> 블로그 보기 | M9: 46215 | N9: 31 | O9: 92 | P9: 142 | Q9: 4 | R9: 2 | S9: 비래동 맛집 | 비래동 한식 | T9: 36.352251 | U9: 127.44314
A10: pending | B10: 대덕구 | C10: 옥천순대매운족발 | D10: 한식>순대,순댓국 | E10: 67 | F10: 최근 12개월 블로그 100건 | G10: 대전광역시 대덕구 송촌동 565-31 | H10: 대전광역시 대덕구 송촌로 9 | I10: =HYPERLINK("https://search.naver.com/search.naver?where=blog&query=%EC%98%A5%EC%B2%9C%EC%88%9C%EB%8C%80%EB%A7%A4%EC%9A%B4%EC%A1%B1%EB%B0%9C+%EB%8C%80%EB%8D%95%EA%B5%AC","블로그 보기") -> 블로그 보기 | M10: 46220 | N10: 100 | O10: 94 | P10: 1483 | Q10: 3 | R10: 2 | S10: 대덕구 고기 | 대덕구 국밥 | T10: 36.356477 | U10: 127.44383
A11: pending | B11: 대덕구 | C11: 양평칼국수콩국수 본점 | D11: 음식점>한식>칼국수,만두 | E11: 66 | F11: 지역성: 본점, 칼국수; 최근 12개월 블로그 100건 | G11: 대전광역시 대덕구 중리동 166-10 | H11: 대전광역시 대덕구 중리남로28번길 1 | I11: =HYPERLINK("https://search.naver.com/search.naver?where=blog&query=%EC%96%91%ED%8F%89%EC%B9%BC%EA%B5%AD%EC%88%98%EC%BD%A9%EA%B5%AD%EC%88%98+%EB%B3%B8%EC%A0%90+%EB%8C%80%EB%8D%95%EA%B5%AC","블로그 보기") -> 블로그 보기 | J11: =HYPERLINK("https://www.instagram.com/yangpyeong_kalguksu","업체 보기") -> 업체 보기 | M11: 46223 | N11: 100 | O11: 96 | P11: 1224 | Q11: 1 | R11: 1 | S11: 대덕구 칼국수 | T11: 36.36113 | U11: 127.42855
A12: pending | B12: 대덕구 | C12: 양평칼국수 | D12: 한식>칼국수,만두 | E12: 65 | F12: 지역성: 칼국수; 최근 12개월 블로그 100건 | G12: 대전광역시 대덕구 덕암동 3-24 | H12: 대전광역시 대덕구 덕암로265번길 105 | I12: =HYPERLINK("https://search.naver.com/search.naver?where=blog&query=%EC%96%91%ED%8F%89%EC%B9%BC%EA%B5%AD%EC%88%98+%EB%8C%80%EB%8D%95%EA%B5%AC","블로그 보기") -> 블로그 보기 | M12: 46220 | N12: 100 | O12: 100 | P12: 540 | Q12: 3 | R12: 0 | S12: 대덕구 칼국수 | 신탄진 칼국수 | 신탄진 한식 | T12: 36.447082 | U12: 127.42132
A13: pending | B13: 대덕구 | C13: 만나숯불구이 중리동본점 | D13: 한식>육류,고기요리 | E13: 64 | F13: 지역성: 본점; 최근 12개월 블로그 100건 | G13: 대전광역시 대덕구 중리동 363-33 1층 | H13: 대전광역시 대덕구 중리로75번길 20 1층 | I13: =HYPERLINK("https://search.naver.com/search.naver?where=blog&query=%EB%A7%8C%EB%82%98%EC%88%AF%EB%B6%88%EA%B5%AC%EC%9D%B4+%EC%A4%91%EB%A6%AC%EB%8F%99%EB%B3%B8%EC%A0%90+%EB%8C%80%EB%8D%95%EA%B5%AC","블로그 보기") -> 블로그 보기 | J13: =HYPERLINK("https://blog.naver.com/kong7249","업체 보기") -> 업체 보기 | M13: 46220 | N13: 100 | O13: 90 | P13: 518 | Q13: 2 | R13: 1 | S13: 대덕구 노포 | T13: 36.365839 | U13: 127.42394
A14: pending | B14: 대덕구 | C14: 성채숯불구이 신탄진 | D14: 한식>육류,고기요리 | E14: 63 | F14: 최근 12개월 블로그 74건 | G14: 대전광역시 대덕구 신탄진동 121-1 1층 | H14: 대전광역시 대덕구 대청로 8 1층 | I14: =HYPERLINK("https://search.naver.com/search.naver?where=blog&query=%EC%84%B1%EC%B1%84%EC%88%AF%EB%B6%88%EA%B5%AC%EC%9D%B4+%EC%8B%A0%ED%83%84%EC%A7%84+%EB%8C%80%EB%8D%95%EA%B5%AC","블로그 보기") -> 블로그 보기 | J14: =HYPERLINK("https://www.instagram.com/scbbq.sintan_official/","업체 보기") -> 업체 보기 | M14: 46219 | N14: 74 | O14: 87 | P14: 358 | Q14: 4 | R14: 0 | S14: 대덕구 고기 | 신탄진 고기 | 신탄진 맛집 | 신탄진 한식 | T14: 36.451136 | U14: 127.42949
A15: pending | B15: 대덕구 | C15: 연탄구이 | D15: 한식>육류,고기요리 | E15: 63 | F15: 최근 12개월 블로그 100건 | G15: 대전광역시 대덕구 오정동 445-14 | H15: 대전광역시 대덕구 한남로88번길 6 | I15: =HYPERLINK("https://search.naver.com/search.naver?where=blog&query=%EC%97%B0%ED%83%84%EA%B5%AC%EC%9D%B4+%EB%8C%80%EB%8D%95%EA%B5%AC","블로그 보기") -> 블로그 보기 | M15: 46220 | N15: 100 | O15: 97 | P15: 724 | Q15: 3 | R15: 1 | S15: 대덕구 고기 | 대덕구 노포 | T15: 36.351141 | U15: 127.41886
A16: pending | B16: 대덕구 | C16: 원조설악추어탕삼계탕 | D16: 음식점>한식 | E16: 63 | F16: 최근 12개월 블로그 100건 | G16: 대전광역시 대덕구 덕암동 8-15 원조설악추어탕삼계탕 | H16: 대전광역시 대덕구 덕암북로48번길 9 원조설악추어탕삼계탕 | I16: =HYPERLINK("https://search.naver.com/search.naver?where=blog&query=%EC%9B%90%EC%A1%B0%EC%84%A4%EC%95%85%EC%B6%94%EC%96%B4%ED%83%95%EC%82%BC%EA%B3%84%ED%83%95+%EB%8C%80%EB%8D%95%EA%B5%AC","블로그 보기") -> 블로그 보기 | M16: 46218 | N16: 100 | O16: 98 | P16: 1144 | Q16: 2 | R16: 2 | S16: 대덕구 삼계탕 | 신탄진 삼계탕 | T16: 36.445228 | U16: 127.42232
A17: rejected | B17: 대덕구 | C17: 식당가 신탄진휴게소 서울방향 | D17: 음식점>한식 | E17: 62 | F17: 최근 12개월 블로그 100건 | G17: 대전광역시 대덕구 상서동 236-1 | H17: 대전광역시 대덕구 산업단지로 27 | I17: =HYPERLINK("https://search.naver.com/search.naver?where=blog&query=%EC%8B%9D%EB%8B%B9%EA%B0%80+%EC%8B%A0%ED%83%84%EC%A7%84%ED%9C%B4%EA%B2%8C%EC%86%8C+%EC%84%9C%EC%9A%B8%EB%B0%A9%ED%96%A5+%EB%8C%80%EB%8D%95%EA%B5%AC","블로그 보기") -> 블로그 보기 | M17: 46198 | N17: 100 | O17: 91 | P17: 574 | Q17: 2 | R17: 2 | S17: 대덕구 국밥 | 신탄진 국밥 | T17: 36.426791 | U17: 127.41855
A18: pending | B18: 대덕구 | C18: 장수촌 중리점 | D18: 한식>백숙,삼계탕 | E18: 62 | F18: 최근 12개월 블로그 58건 | G18: 대전광역시 대덕구 중리동 499-4 | H18: 대전광역시 대덕구 송촌북로5번길 10-11 | I18: =HYPERLINK("https://search.naver.com/search.naver?where=blog&query=%EC%9E%A5%EC%88%98%EC%B4%8C+%EC%A4%91%EB%A6%AC%EC%A0%90+%EB%8C%80%EB%8D%95%EA%B5%AC","블로그 보기") -> 블로그 보기 | M18: 46217 | N18: 58 | O18: 98 | P18: 236 | Q18: 3 | R18: 1 | S18: 대덕구 삼계탕 | 대덕구 한식 | T18: 36.363261 | U18: 127.43629
A19: pending | B19: 대덕구 | C19: 신탄짬뽕 대전신탄진본점 | D19: 중식>중식당 | E19: 61 | F19: 지역성: 본점, 대전; 최근 12개월 블로그 100건 | G19: 대전광역시 대덕구 신탄진동 121-25 1층 | H19: 대전광역시 대덕구 신탄진동로7번길 74 1층 | I19: =HYPERLINK("https://search.naver.com/search.naver?where=blog&query=%EC%8B%A0%ED%83%84%EC%A7%AC%EB%BD%95+%EB%8C%80%EC%A0%84%EC%8B%A0%ED%83%84%EC%A7%84%EB%B3%B8%EC%A0%90+%EC%8B%A0%ED%83%84%EC%A7%84%EB%8F%99","블로그 보기") -> 블로그 보기 | M19: 46220 | N19: 100 | O19: 55 | P19: 391 | Q19: 1 | R19: 0 | S19: 신탄진 중식 | T19: 36.450884 | U19: 127.42958
A20: pending | B20: 대덕구 | C20: 왕실전골칼국수 선비마을점 | D20: 한식>칼국수,만두 | E20: 61 | F20: 지역성: 칼국수; 최근 12개월 블로그 23건 | G20: 대전광역시 대덕구 송촌동 482-1 | H20: 대전광역시 대덕구 계족산로36번길 67 | I20: =HYPERLINK("https://search.naver.com/search.naver?where=blog&query=%EC%99%95%EC%8B%A4%EC%A0%84%EA%B3%A8%EC%B9%BC%EA%B5%AD%EC%88%98+%EC%84%A0%EB%B9%84%EB%A7%88%EC%9D%84%EC%A0%90+%EB%8C%80%EB%8D%95%EA%B5%AC","블로그 보기") -> 블로그 보기 | M20: 46220 | N20: 23 | O20: 47 | P20: 67 | Q20: 2 | R20: 1 | S20: 대덕구 두부두루치기 | T20: 36.362298 | U20: 127.43885
A21: pending | B21: 대덕구 | C21: 샤브마니아 대전송촌점 | D21: 음식점>일식>샤브샤브 | E21: 60 | F21: 지역성: 대전; 최근 12개월 블로그 100건 | G21: 대전광역시 대덕구 송촌동 447-4 1층 샤브마니아 송촌점 | H21: 대전광역시 대덕구 계족산로81번길 92 1층 샤브마니아 송촌점 | I21: =HYPERLINK("https://search.naver.com/search.naver?where=blog&query=%EC%83%A4%EB%B8%8C%EB%A7%88%EB%8B%88%EC%95%84+%EB%8C%80%EC%A0%84%EC%86%A1%EC%B4%8C%EC%A0%90+%EB%8C%80%EB%8D%95%EA%B5%AC","블로그 보기") -> 블로그 보기 | J21: =HYPERLINK("https://www.instagram.com/1sb.mania","업체 보기") -> 업체 보기 | M21: 46223 | N21: 100 | O21: 94 | P21: 492 | Q21: 1 | R21: 1 | S21: 대덕구 일식 | T21: 36.366555 | U21: 127.43735
A22: pending | B22: 대덕구 | C22: 스텔라떡볶이 대전신탄진점 | D22: 음식점>분식 | E22: 60 | F22: 지역성: 대전; 최근 12개월 블로그 100건 | G22: 대전광역시 대덕구 신탄진동 145-6 1층 | H22: 대전광역시 대덕구 신탄진로 815 1층 | I22: =HYPERLINK("https://search.naver.com/search.naver?where=blog&query=%EC%8A%A4%ED%85%94%EB%9D%BC%EB%96%A1%EB%B3%B6%EC%9D%B4+%EB%8C%80%EC%A0%84%EC%8B%A0%ED%83%84%EC%A7%84%EC%A0%90+%EB%8C%80%EB%8D%95%EA%B5%AC","블로그 보기") -> 블로그 보기 | J22: =HYPERLINK("https://www.stellapick.com/","업체 보기") -> 업체 보기 | M22: 46223 | N22: 100 | O22: 89 | P22: 346 | Q22: 2 | R22: 0 | S22: 대덕구 분식 | 신탄진 분식 | T22: 36.450366 | U22: 127.42876
A23: pending | B23: 대덕구 | C23: 대청골순대국밥전문점 | D23: 한식>순대,순댓국 | E23: 59 | F23: 최근 12개월 블로그 100건 | G23: 대전광역시 대덕구 신탄진동 121-6 | H23: 대전광역시 대덕구 대청로 10 | I23: =HYPERLINK("https://search.naver.com/search.naver?where=blog&query=%EB%8C%80%EC%B2%AD%EA%B3%A8%EC%88%9C%EB%8C%80%EA%B5%AD%EB%B0%A5%EC%A0%84%EB%AC%B8%EC%A0%90+%EB%8C%80%EB%8D%95%EA%B5%AC","블로그 보기") -> 블로그 보기 | J23: =HYPERLINK("https://daecheonggol.creatorlink.net/","업체 보기") -> 업체 보기 | M23: 46220 | N23: 100 | O23: 91 | P23: 845 | Q23: 2 | R23: 1 | S23: 신탄진 국밥 | T23: 36.451202 | U23: 127.42973
A24: rejected | B24: 대덕구 | C24: 손의손 송촌점 | D24: 해물,생선요리>주꾸미요리 | E24: 59 | F24: 최근 12개월 블로그 57건 | G24: 대전광역시 대덕구 송촌동 459-4 2층 201호 | H24: 대전광역시 대덕구 계족산로81번길 64 2층 201호 | I24: =HYPERLINK("https://search.naver.com/search.naver?where=blog&query=%EC%86%90%EC%9D%98%EC%86%90+%EC%86%A1%EC%B4%8C%EC%A0%90+%EB%8C%80%EB%8D%95%EA%B5%AC","블로그 보기") -> 블로그 보기 | J24: =HYPERLINK("https://손의손.com","업체 보기") -> 업체 보기 | M24: 46219 | N24: 57 | O24: 59 | P24: 60 | Q24: 2 | R24: 2 | S24: 대덕구 냉면 | 대덕구 해산물 | T24: 36.36569 | U24: 127.43863
A25: pending | B25: 대덕구 | C25: 얌샘김밥 신탄진점 | D25: 음식점>분식 | E25: 59 | F25: 최근 12개월 블로그 9건 | G25: 대전광역시 대덕구 신탄진동 143-16 1층 | H25: 대전광역시 대덕구 신탄진로 802 1층 | I25: =HYPERLINK("https://search.naver.com/search.naver?where=blog&query=%EC%96%8C%EC%83%98%EA%B9%80%EB%B0%A5+%EC%8B%A0%ED%83%84%EC%A7%84%EC%A0%90+%EB%8C%80%EB%8D%95%EA%B5%AC","블로그 보기") -> 블로그 보기 | J25: =HYPERLINK("https://www.instagram.com/yumsem_official","업체 보기") -> 업체 보기 | M25: 46073 | N25: 9 | O25: 17 | P25: 21 | Q25: 3 | R25: 1 | S25: 대덕구 분식 | 신탄진 분식 | T25: 36.449127 | U25: 127.42943
A26: pending | B26: 대덕구 | C26: 명가네보쌈칼국수 | D26: 한식>칼국수,만두 | E26: 58 | F26: 지역성: 칼국수; 최근 12개월 블로그 22건 | G26: 대전광역시 대덕구 비래동 138-1 | H26: 대전광역시 대덕구 비래동로 30 | I26: =HYPERLINK("https://search.naver.com/search.naver?where=blog&query=%EB%AA%85%EA%B0%80%EB%84%A4%EB%B3%B4%EC%8C%88%EC%B9%BC%EA%B5%AD%EC%88%98+%EB%B9%84%EB%9E%98%EB%8F%99","블로그 보기") -> 블로그 보기 | M26: 46109 | N26: 22 | O26: 73 | P26: 131 | Q26: 1 | R26: 1 | S26: 비래동 한식 | T26: 36.356454 | U26: 127.45067
A27: pending | B27: 대덕구 | C27: 영화반점 | D27: 중식>중식당 | E27: 58 | F27: 최근 12개월 블로그 10건 | G27: 대전광역시 대덕구 신탄진동 139-17 | H27: 대전광역시 대덕구 신탄진동로23번길 46 | I27: =HYPERLINK("https://search.naver.com/search.naver?where=blog&query=%EC%98%81%ED%99%94%EB%B0%98%EC%A0%90+%EC%8B%A0%ED%83%84%EC%A7%84%EB%8F%99","블로그 보기") -> 블로그 보기 | M27: 46145 | N27: 10 | O27: 87 | P27: 102 | Q27: 3 | R27: 0 | S27: 대덕구 중식 | 신탄진 중식 | 신탄진 해산물 | T27: 36.449829 | U27: 127.43154
A28: pending | B28: 대덕구 | C28: 유가옥 설렁탕 본점 | D28: 한식>곰탕,설렁탕 | E28: 58 | F28: 지역성: 본점; 최근 12개월 블로그 54건 | G28: 대전광역시 대덕구 중리동 202-1 | H28: 대전광역시 대덕구 한밭대로 1161 | I28: =HYPERLINK("https://search.naver.com/search.naver?where=blog&query=%EC%9C%A0%EA%B0%80%EC%98%A5+%EC%84%A4%EB%A0%81%ED%83%95+%EB%B3%B8%EC%A0%90+%EB%8C%80%EB%8D%95%EA%B5%AC","블로그 보기") -> 블로그 보기 | M28: 46220 | N28: 54 | O28: 75 | P28: 110 | Q28: 1 | R28: 1 | S28: 대덕구 냉면 | T28: 36.359309 | U28: 127.42749
A29: pending | B29: 대덕구 | C29: 제주은희네해장국 대전신탄진점 | D29: 한식>해장국 | E29: 58 | F29: 지역성: 대전; 최근 12개월 블로그 61건 | G29: 대전광역시 대덕구 상서동 396-3 나동 1층 | H29: 대전광역시 대덕구 신탄진로 490 나동 1층 | I29: =HYPERLINK("https://search.naver.com/search.naver?where=blog&query=%EC%A0%9C%EC%A3%BC%EC%9D%80%ED%9D%AC%EB%84%A4%ED%95%B4%EC%9E%A5%EA%B5%AD+%EB%8C%80%EC%A0%84%EC%8B%A0%ED%83%84%EC%A7%84%EC%A0%90+%EB%82%98%EB%8F%99","블로그 보기") -> 블로그 보기 | M29: 46220 | N29: 61 | O29: 96 | P29: 193 | Q29: 1 | R29: 1 | S29: 신탄진 국밥 | T29: 36.423151 | U29: 127.41985
A30: pending | B30: 대덕구 | C30: 짬뽕지존 신탄진점 | D30: 음식점>중식당 | E30: 58 | F30: 최근 12개월 블로그 9건 | G30: 대전광역시 대덕구 상서동 282 1,2층 | H30: 대전광역시 대덕구 신탄진로 578 1,2층 | I30: =HYPERLINK("https://search.naver.com/search.naver?where=blog&query=%EC%A7%AC%EB%BD%95%EC%A7%80%EC%A1%B4+%EC%8B%A0%ED%83%84%EC%A7%84%EC%A0%90+%EB%8C%80%EB%8D%95%EA%B5%AC","블로그 보기") -> 블로그 보기 | M30: 46135 | N30: 9 | O30: 35 | P30: 43 | Q30: 2 | R30: 2 | S30: 대덕구 중식 | 신탄진 중식 | T30: 36.430202 | U30: 127.42222
A31: pending | B31: 대덕구 | C31: 한밭신화수산 | D31: 한식>생선회 | E31: 58 | F31: 최근 12개월 블로그 100건 | G31: 대전광역시 대덕구 오정동 736 | H31: 대전광역시 대덕구 대전천북로 350 | I31: =HYPERLINK("https://search.naver.com/search.naver?where=blog&query=%ED%95%9C%EB%B0%AD%EC%8B%A0%ED%99%94%EC%88%98%EC%82%B0+%EB%8C%80%EB%8D%95%EA%B5%AC","블로그 보기") -> 블로그 보기 | M31: 46220 | N31: 100 | O31: 91 | P31: 402 | Q31: 2 | R31: 1 | S31: 대덕구 해산물 | T31: 36.356188 | U31: 127.40547
A32: rejected | B32: 대덕구 | C32: 김밥천국 | D32: 음식점>분식 | E32: 57 | F32: 최근 12개월 블로그 16건 | G32: 대전광역시 대덕구 석봉동 309-11 김밥천국 | H32: 대전광역시 대덕구 대덕대로 1554 김밥천국 | I32: =HYPERLINK("https://search.naver.com/search.naver?where=blog&query=%EA%B9%80%EB%B0%A5%EC%B2%9C%EA%B5%AD+%EB%8C%80%EB%8D%95%EA%B5%AC","블로그 보기") -> 블로그 보기 | M32: 46217 | N32: 16 | O32: 92 | P32: 195 | Q32: 2 | R32: 1 | S32: 신탄진 분식 | T32: 36.449074 | U32: 127.42053
A33: pending | B33: 대덕구 | C33: 동죽칼국수 | D33: 한식>칼국수,만두 | E33: 57 | F33: 지역성: 칼국수; 최근 12개월 블로그 96건 | G33: 대전광역시 대덕구 목상동 148-6 동죽칼국수 | H33: 대전광역시 대덕구 대덕대로1458번길 23 동죽칼국수 | I33: =HYPERLINK("https://search.naver.com/search.naver?where=blog&query=%EB%8F%99%EC%A3%BD%EC%B9%BC%EA%B5%AD%EC%88%98+%EB%8C%80%EB%8D%95%EA%B5%AC","블로그 보기") -> 블로그 보기 | M33: 46222 | N33: 96 | O33: 94 | P33: 464 | Q33: 1 | R33: 0 | S33: 신탄진 칼국수 | T33: 36.448214 | U33: 127.41143
A34: pending | B34: 대덕구 | C34: 청년다방 대전송촌점 | D34: 음식점>분식 | E34: 57 | F34: 지역성: 대전; 최근 12개월 블로그 100건 | G34: 대전광역시 대덕구 송촌동 449-6 | H34: 대전광역시 대덕구 송촌북로36번길 11 | I34: =HYPERLINK("https://search.naver.com/search.naver?where=blog&query=%EC%B2%AD%EB%85%84%EB%8B%A4%EB%B0%A9+%EB%8C%80%EC%A0%84%EC%86%A1%EC%B4%8C%EC%A0%90+%EB%8C%80%EB%8D%95%EA%B5%AC","블로그 보기") -> 블로그 보기 | J34: =HYPERLINK("http://www.youngdabang.com/","업체 보기") -> 업체 보기 | M34: 46220 | N34: 100 | O34: 95 | P34: 487 | Q34: 1 | R34: 0 | S34: 대덕구 분식 | T34: 36.365813 | U34: 127.43669
A35: pending | B35: 대덕구 | C35: 홍굴이 부추손칼국수 | D35: 한식>칼국수,만두 | E35: 57 | F35: 지역성: 칼국수; 최근 12개월 블로그 100건 | G35: 대전광역시 대덕구 송촌동 503-7 | H35: 대전광역시 대덕구 선비마을로5번길 3 | I35: =HYPERLINK("https://search.naver.com/search.naver?where=blog&query=%ED%99%8D%EA%B5%B4%EC%9D%B4+%EB%B6%80%EC%B6%94%EC%86%90%EC%B9%BC%EA%B5%AD%EC%88%98+%EB%8C%80%EB%8D%95%EA%B5%AC","블로그 보기") -> 블로그 보기 | M35: 46223 | N35: 100 | O35: 93 | P35: 560 | Q35: 1 | R35: 0 | S35: 대덕구 칼국수 | T35: 36.361877 | U35: 127.44567
A36: pending | B36: 대덕구 | C36: 황금칼국수 | D36: 한식>칼국수,만두 | E36: 57 | F36: 지역성: 칼국수; 최근 12개월 블로그 100건 | G36: 대전광역시 대덕구 읍내동 327-3 황금칼국수 | H36: 대전광역시 대덕구 대전로 1357 황금칼국수 | I36: =HYPERLINK("https://search.naver.com/search.naver?where=blog&query=%ED%99%A9%EA%B8%88%EC%B9%BC%EA%B5%AD%EC%88%98+%EB%8C%80%EB%8D%95%EA%B5%AC","블로그 보기") -> 블로그 보기 | J36: =HYPERLINK("https://www.instagram.com/hwang_geum_kalgugsu","업체 보기") -> 업체 보기 | M36: 46222 | N36: 100 | O36: 86 | P36: 601 | Q36: 1 | R36: 0 | S36: 대덕구 두부두루치기 | T36: 36.374945 | U36: 127.42003
A37: pending | B37: 대덕구 | C37: 일품돼지국밥 대전IC점 | D37: 한식>국밥 | E37: 56 | F37: 지역성: 대전; 최근 12개월 블로그 100건 | G37: 대전광역시 대덕구 비래동 557-1 1층 일품돼지국밥 대전IC점 | H37: 대전광역시 대덕구 동서대로 1770 1층 일품돼지국밥 대전IC점 | I37: =HYPERLINK("https://search.naver.com/search.naver?where=blog&query=%EC%9D%BC%ED%92%88%EB%8F%BC%EC%A7%80%EA%B5%AD%EB%B0%A5+%EB%8C%80%EC%A0%84IC%EC%A0%90+%EB%8C%80%EB%8D%95%EA%B5%AC","블로그 보기") -> 블로그 보기 | M37: 46220 | N37: 100 | O37: 80 | P37: 284 | Q37: 1 | R37: 0 | S37: 대덕구 국밥 | T37: 36.353488 | U37: 127.444
A38: pending | B38: 대덕구 | C38: 포대포소곱창구이 | D38: 한식>곱창,막창,양 | E38: 56 | F38: 최근 12개월 블로그 100건 | G38: 대전광역시 대덕구 송촌동 548-20 | H38: 대전광역시 대덕구 선비마을로 22 | I38: =HYPERLINK("https://search.naver.com/search.naver?where=blog&query=%ED%8F%AC%EB%8C%80%ED%8F%AC%EC%86%8C%EA%B3%B1%EC%B0%BD%EA%B5%AC%EC%9D%B4+%EB%8C%80%EB%8D%95%EA%B5%AC","블로그 보기") -> 블로그 보기 | M38: 46222 | N38: 100 | O38: 92 | P38: 1303 | Q38: 1 | R38: 1 | S38: 대덕구 고기 | T38: 36.362818 | U38: 127.44712
A39: pending | B39: 대덕구 | C39: 미카도스시 대전신탄진점 | D39: 음식점>일식>초밥,롤 | E39: 55 | F39: 지역성: 대전; 최근 12개월 블로그 65건 | G39: 대전광역시 대덕구 신탄진동 121-33 103호 | H39: 대전광역시 대덕구 대청로 12 103호 | I39: =HYPERLINK("https://search.naver.com/search.naver?where=blog&query=%EB%AF%B8%EC%B9%B4%EB%8F%84%EC%8A%A4%EC%8B%9C+%EB%8C%80%EC%A0%84%EC%8B%A0%ED%83%84%EC%A7%84%EC%A0%90+%EB%8C%80%EB%8D%95%EA%B5%AC","블로그 보기") -> 블로그 보기 | J39: =HYPERLINK("http://mikadosushi.co.kr/","업체 보기") -> 업체 보기 | M39: 46220 | N39: 65 | O39: 43 | P39: 116 | Q39: 1 | R39: 0 | S39: 신탄진 일식 | T39: 36.451306 | U39: 127.43015
A40: pending | B40: 대덕구 | C40: 상하이양꼬치 | D40: 중식>양꼬치 | E40: 55 | F40: 최근 12개월 블로그 100건 | G40: 대전광역시 대덕구 송촌동 456-12 | H40: 대전광역시 대덕구 송촌북로16번길 43 | I40: =HYPERLINK("https://search.naver.com/search.naver?where=blog&query=%EC%83%81%ED%95%98%EC%9D%B4%EC%96%91%EA%BC%AC%EC%B9%98+%EB%8C%80%EB%8D%95%EA%B5%AC","블로그 보기") -> 블로그 보기 | M40: 46171 | N40: 100 | O40: 92 | P40: 568 | Q40: 1 | R40: 1 | S40: 대덕구 중식 | T40: 36.364657 | U40: 127.43879
...

Sheet 검토 가이드
A1: 식당 후보 검토 가이드
A4: 후보 검토 시트에서 필터를 사용하고, 블로그 보기 링크로 최근 운영 상태와 여행 추천 가치를 확인하세요.
A6: 상태 | B6: 의미 | C6: 사용 기준
A7: pending | B7: 미검토 | C7: 아직 사람이 확인하지 않은 후보
A8: approved | B8: 승인 | C8: 최종 추천 목록에 포함할 후보
A9: hold | B9: 보류 | C9: 영업 여부나 중복 여부를 추가 확인할 후보
A10: rejected | B10: 제외 | C10: 최종 추천 목록에서 제외할 후보
A13: 대표 제외 사유 | B13: 판정 예시 | D13: 수작업 확인 항목
A14: 기존 목록 중복 | B14: 기존 추천 식당과 같은 업소 | D14: 영업시간 · 브레이크타임 · 휴무일
A15: 폐업·휴업 | B15: 최근 영업 사실을 확인할 수 없음 | D15: 대표 메뉴 · 가격대
A16: 배달 위주 | B16: 여행 중 방문보다 배달·포장 중심 | D16: 주차 · 예약 · 웨이팅
A17: 일반 프랜차이즈 | B17: 지역 고유성이 낮고 어디서나 방문 가능 | D17: 혼밥 · 가족 · 단체 방문 적합성
A18: 비식당 | B18: 먹자거리·명소·마트 등 개별 음식점이 아님 | D18: 최근 1년 실제 방문 리뷰
A19: 추천 가치 낮음 | B19: 대표 메뉴나 방문 이유가 불명확 | D19: 공식 채널 또는 지도 정보와 교차 확인
A20: 정보 부족 | B20: 최신 운영·메뉴 정보를 교차 확인하기 어려움 | D20: 마지막 확인 날짜 기록
A23: 주의: 추천 점수와 블로그 검색량은 승인 판정이 아니라 검토 순서를 정하기 위한 참고값입니다.
